<?xml version="1.0" ?>
<robot xmlns:xacro="http://www.ros.org/wiki/xacro">

<xacro:property name="connect_offset" value="0.02633" />
<xacro:property name="thigh_offset_y" value="-0.0645" />
<xacro:property name="thigh_offset_z" value="-0.0145" />



<xacro:macro name="phantomx" params="parent *origin">

      <joint name="j_phantomx_attachment" type="fixed">
        <parent link="${parent}"/>
        <child link="MP_BODY"/>
        <insert_block name="origin" />
      </joint>


      <link name="MP_BODY">
        <inertial>
          <mass value="1000" />
          <origin rpy="0 0 0" xyz="0 0 0.035" />
          <inertia ixx="1000" ixy="0" ixz="0" iyy="1000" iyz="0" izz="1000" />
        </inertial>
        <collision>
          <origin rpy="0 0 0" xyz="0 0 0.035" />
          <geometry>
            <box size="0.03 0.03 0.07" />
          </geometry>
        </collision>
        <visual>
          <origin rpy="0 0 0" xyz="0.0 0.0 0.035" />
          <geometry>
            <box size="0.03 0.03 0.07" />
          </geometry>
        </visual>
      </link>      


      <gazebo reference="MP_BODY">    
        <material>Gazebo/Grey</material>
      </gazebo>


    <xacro:leg_l xyz="0.1248 -0.06164  0.001116"  rpy="0 4.7123 0.7853981633974483" suffix="rf"/>


</xacro:macro>

<xacro:macro name="m_link_box" params="name origin_xyz origin_rpy size mass ixx ixy ixz iyy iyz izz">
  <link name="${name}">
    <inertial>
      <mass value="${mass}" />
      <origin rpy="${origin_rpy}" xyz="${origin_xyz}" />
      <inertia ixx="${ixx}" ixy="${ixy}" ixz="${ixz}" iyy="${iyy}" iyz="${iyz}" izz="${izz}" />
    </inertial>
    <collision>
      <origin rpy="${origin_rpy}" xyz="${origin_xyz}" />
      <geometry>
        <box size="${size}" />
      </geometry>
    </collision>
    <visual>
      <origin rpy="${origin_rpy}" xyz="${origin_xyz}" />
      <geometry>
        <box size="${size}" />
      </geometry>
    </visual>
  </link>
</xacro:macro>



 <xacro:macro name="leg_l" params="xyz rpy suffix">



  <link name="c1_${suffix}">
    <inertial>
      <origin xyz="0 -${connect_offset} 0" rpy="0 0 0"  />
      <mass value="0.024357719"/>
     <inertia ixx="0.0051411124"  ixy="-0.00057530255"  ixz="-0.000024729049" iyy="0.0081915737" iyz="-0.000019223094" izz="0.0011379812" />
    </inertial>
    <visual>
      <origin xyz="0 -0.0252 0" rpy="0 0 0"  />
      <geometry>
        <!--box size="0.045 0.022 0.0325" /-->
        <mesh filename="package://move_one_leg/meshes/connect.STL"  scale="1 1 1"/>
      </geometry>
      <material name="Grey">
        <color rgba="0.20 0.20 0.20 1.0"/>
      </material>
    </visual>
    <collision>
      <origin xyz="0 -${connect_offset} 0" rpy="0 0 0"  />
      <geometry>
        <mesh filename="package://move_one_leg/meshes/connect_coll.STL"  scale="1 1 1"/>
      </geometry>
    </collision>
  </link>


  <link name="c2_${suffix}">
    <inertial>
      <origin xyz="0 -${connect_offset} 0" rpy="0 0 0"  />
      <mass value="0.024357719"/>
     <inertia ixx="0.0051411124"  ixy="-0.00057530255"  ixz="-0.000024729049" iyy="0.0081915737" iyz="-0.000019223094" izz="0.0011379812" />
    </inertial>
    <visual>
      <origin xyz="0 -0.0252 0" rpy="0 0 0"  />
      <geometry>
        <!--box size="0.045 0.022 0.0325" /-->
        <mesh filename="package://move_one_leg/meshes/connect.STL"  scale="1 1 1"/>
      </geometry>
      <material name="Grey">
        <color rgba="0.20 0.20 0.20 1.0"/>
      </material>
    </visual>
    <collision>
      <origin xyz="0 -${connect_offset} 0" rpy="0 0 0"  />
      <geometry>
        <mesh filename="package://move_one_leg/meshes/connect_coll.STL"  scale="1 1 1"/>
      </geometry>
    </collision>
  </link>



  <link name="thigh_${suffix}">
    <inertial>
      <origin xyz="0 0 0" rpy="0 0 0"  />
      <mass value="0.024357719"/>
     <inertia ixx="0.0051411124"  ixy="-0.00057530255"  ixz="-0.000024729049" iyy="0.0081915737" iyz="-0.000019223094" izz="0.0011379812" />
    </inertial>
    <visual>
      <origin xyz="0 0 0" rpy="0 0 0"  />
      <geometry>
        <!--box size="0.045 0.022 0.0325" /-->
        <mesh filename="package://move_one_leg/meshes/thigh_l.STL"  scale="1 1 1"/>
      </geometry>
      <material name="Grey">
        <color rgba="0.20 0.20 0.20 1.0"/>
      </material>
    </visual>
    <collision>
      <origin xyz="0 0 0" rpy="0 0 0"  />
      <geometry>
        <mesh filename="package://move_one_leg/meshes/thigh_l_coll.STL"  scale="1 1 1"/>
      </geometry>
    </collision>
  </link>



  <link name="tibia_${suffix}">
    <inertial>
      <origin xyz="0 0 0" rpy="0 0 0"  />
      <mass value="0.024357719"/>
     <inertia ixx="0.0051411124"  ixy="-0.00057530255"  ixz="-0.000024729049" iyy="0.0081915737" iyz="-0.000019223094" izz="0.0011379812" />
    </inertial>
    <visual>
      <origin xyz="0 0 0" rpy="0 0 0"  />
      <geometry>
        <!--box size="0.045 0.022 0.0325" /-->
        <mesh filename="package://move_one_leg/meshes/tibia_l.STL"  scale="1 1 1"/>
      </geometry>
      <material name="Grey">
        <color rgba="0.20 0.20 0.20 1.0"/>
      </material>
    </visual>
    <collision>
      <origin xyz="0 0 0" rpy="0 0 0"  />
      <geometry>
        <mesh filename="package://move_one_leg/meshes/tibia_l_coll.STL"  scale="1 1 1"/>
      </geometry>
    </collision>
  </link>



  <joint name="j_c1_${suffix}" type="revolute">
    <parent link="MP_BODY"/>
    <child link="c1_${suffix}"/>
    <origin xyz="0 0 0.06" rpy="-1.57 0 0" />
    <axis xyz="1 0 0" />
    <limit effort="2.8" velocity="1" lower="-2.6179939" upper="2.6179939" />
  </joint>

  <joint name="j_c2_${suffix}" type="fixed">
    <parent link="c1_${suffix}"/>
    <child link="c2_${suffix}"/>
    <origin xyz="0 -0.054 0" rpy="0 1.5704 3.14159" />
  </joint>


  <joint name="j_thigh_${suffix}" type="revolute">
    <parent link="c2_${suffix}"/>
    <child link="thigh_${suffix}"/>
    <origin xyz="0 0 0" rpy=" 0 3.14159 3.14159" />
    <axis xyz="1 0 0" />
    <limit effort="2.8" velocity="1" lower="-2.6179939" upper="2.6179939" />
  </joint>

  <joint name="j_tibia_${suffix}" type="revolute">
    <parent link="thigh_${suffix}"/>
    <child link="tibia_${suffix}"/>
    <origin xyz="0 ${thigh_offset_y} ${thigh_offset_z}" rpy="-1.03 0 3.14159" />
    <axis xyz="1 0 0" />
    <limit effort="2.8" velocity="1" lower="-2.6179939" upper="2.6179939" />
  </joint>



   <transmission name="t_c1_${suffix}">
    <type>transmission_interface/SimpleTransmission</type>
    <joint name="j_c1_${suffix}">
      <hardwareInterface>hardware_interface/EffortJointInterface</hardwareInterface>    
    </joint>
    <actuator name="m_c1_${suffix}">
      <hardwareInterface>hardware_interface/EffortJointInterface</hardwareInterface>
      <mechanicalReduction>1</mechanicalReduction>
    </actuator>
  </transmission>


   <transmission name="t_thigh_${suffix}">
    <type>transmission_interface/SimpleTransmission</type>
    <joint name="j_thigh_${suffix}">
      <hardwareInterface>hardware_interface/EffortJointInterface</hardwareInterface>    
    </joint>
    <actuator name="m_thigh_${suffix}">
      <hardwareInterface>hardware_interface/EffortJointInterface</hardwareInterface>
      <mechanicalReduction>1</mechanicalReduction>
    </actuator>
  </transmission>


   <transmission name="t_tibia_${suffix}">
    <type>transmission_interface/SimpleTransmission</type>
    <joint name="j_tibia_${suffix}">
      <hardwareInterface>hardware_interface/EffortJointInterface</hardwareInterface>
    </joint>
    <actuator name="m_tibia_${suffix}">
      <hardwareInterface>hardware_interface/EffortJointInterface</hardwareInterface>
      <mechanicalReduction>1</mechanicalReduction>
    </actuator>
  </transmission>



  <gazebo reference="c1_${suffix}">    
    <material>Gazebo/Grey</material>
  </gazebo>

  <gazebo reference="c2_${suffix}">    
    <material>Gazebo/Grey</material>
  </gazebo>

  <gazebo reference="thigh_${suffix}">    
    <material>Gazebo/Grey</material>
  </gazebo>

  <gazebo reference="tibia_${suffix}">    
    <material>Gazebo/Grey</material>
  </gazebo>

  
</xacro:macro>





</robot>
